<?xml version="1.0" encoding="utf-8"?>
<robot xmlns:xacro="http://www.ros.org/wiki/xacro" name="hand">
    <xacro:include filename="$(find custom_description)/robots/utils.xacro"/>
    <xacro:macro name="custom_hand" params="arm_id tcp_xyz tcp_rpy tcp2_xyz tcp2_rpy camera_xyz camera_rpy">

        <link name="${arm_id}_hand">
            <xacro:visual name="hand" />
            <xacro:visual name="camera" xyz="${camera_xyz}" rpy="${camera_rpy}" />
            <xacro:collision name="hand"/>
            <xacro:collision name="camera" xyz="${camera_xyz}" rpy="${camera_rpy}" />
        </link>

        <joint name="${arm_id}_hand_joint" type="fixed">
            <parent link="${arm_id}_link8"/>
            <child link="${arm_id}_hand" />
            <origin xyz="0 0 0" rpy="0 0 ${-pi/4}" />
        </joint>

        <link name="${arm_id}_hand_sc">
            <collision>
                <geometry>
                    <sphere radius="0.14"/>
                </geometry>
            </collision>
            <collision>
                <origin xyz="0 0 0.14"/>
                <geometry>
                    <box size="0.04 0.14 0.14"/>
                </geometry>
            </collision>
        </link>
        
        <joint name="${arm_id}_hand_sc_joint" type="fixed">
            <parent link="${arm_id}_hand" />
            <child link="${arm_id}_hand_sc" />
        </joint>

        <xacro:tcp name="grasp-tcp" parent="hand" xyz="${tcp_xyz}" rpy="${tcp_rpy}"/>
        <xacro:tcp name="push-tcp" parent="hand" xyz="${tcp2_xyz}" rpy="${tcp2_rpy}"/>

        <link name="${arm_id}_leftfinger">
            <xacro:visual name="finger"/>
            <xacro:collision name="finger"/>
        </link>
        <link name="${arm_id}_rightfinger">
            <xacro:visual name="finger" rpy="0 0 ${pi}"/>
            <xacro:collision name="finger" rpy="0 0 ${pi}"/>
        </link>

        <joint name="${arm_id}_finger_joint1" type="prismatic">
            <parent link="${arm_id}_hand" />
            <child link="${arm_id}_leftfinger" />
            <origin xyz="0 0 0.0584" rpy="0 0 0" />
            <axis xyz="0 1 0" />
            <limit effort="100" lower="0.0" upper="0.04" velocity="0.2" />
            <dynamics damping="0.3" />
        </joint>
        <joint name="${arm_id}_finger_joint2" type="prismatic">
            <parent link="${arm_id}_hand" />
            <child link="${arm_id}_rightfinger" />
            <origin xyz="0 0 0.0584" rpy="0 0 0" />
            <axis xyz="0 -1 0" />
            <limit effort="100" lower="0.0" upper="0.04" velocity="0.2" />
            <mimic joint="${arm_id}_finger_joint1" />
            <dynamics damping="0.3" />
        </joint>
    </xacro:macro>
</robot>
