<?xml version="1.0" encoding="utf-8"?>
<robot xmlns:xacro="http://www.ros.org/wiki/xacro" name="hand">
    <xacro:macro name="custom_hand" params="arm_id tcp_xyz tcp_rpy tcp2_xyz tcp2_rpy camera_xyz camera_rpy">

        <link name="${arm_id}_hand">
            <visual>
                <geometry>
                    <mesh filename="package://custom_description/meshes/visual/hand.dae" />
                </geometry>
            </visual>
            <collision>
                <geometry>
                    <mesh filename="package://custom_description/meshes/collision/hand.stl" />
                </geometry>
            </collision>
        </link>

        <joint name="${arm_id}_hand_joint" type="fixed">
            <parent link="${arm_id}_link8"/>
            <child link="${arm_id}_hand" />
            <origin xyz="0 0 0" rpy="0 0 ${-pi/4}" />
        </joint>

        <link name="${arm_id}_hand_sc">
            <visual>
                <geometry>
                    <mesh filename="package://custom_description/meshes/visual/camera.dae" />
                </geometry>
            </visual>
            <collision>
                <geometry>
                    <mesh filename="package://custom_description/meshes/collision/camera.stl" />
                </geometry>
            </collision>
        </link>

        <joint name="${arm_id}_hand_sc_joint" type="fixed">
            <origin xyz="${camera_xyz}" rpy="${camera_rpy}"/>
            <parent link="${arm_id}_hand" />
            <child link="${arm_id}_hand_sc" />
        </joint>

        <link name="${arm_id}_hand_tcp" />
        <link name="${arm_id}_hand_tcp2" />

        <joint name="${arm_id}_hand_tcp_joint" type="fixed">
            <origin xyz="${tcp_xyz}" rpy="${tcp_rpy}" />
            <parent link="${arm_id}_hand" />
            <child link="${arm_id}_hand_tcp" />
        </joint>
        <joint name="${arm_id}_hand_tcp2_joint" type="fixed">
            <origin xyz="${tcp2_xyz}" rpy="${tcp2_rpy}" />
            <parent link="${arm_id}_hand" />
            <child link="${arm_id}_hand_tcp2" />
        </joint>

        <link name="${arm_id}_leftfinger">
            <visual>
                <geometry>
                    <mesh filename="package://custom_description/meshes/visual/finger.dae" />
                </geometry>
            </visual>
            <collision>
                <geometry>
                    <mesh filename="package://custom_description/meshes/collision/finger.stl"/>
                </geometry>
            </collision>
        </link>
        <link name="${arm_id}_rightfinger">
            <visual>
                <origin xyz="0 0 0" rpy="0 0 ${pi}" />
                <geometry>
                    <mesh filename="package://custom_description/meshes/visual/finger.dae" />
                </geometry>
            </visual>
            <collision>
                <origin xyz="0 0 0" rpy="0 0 ${pi}"/>
                <geometry>
                    <mesh filename="package://custom_description/meshes/collision/finger.stl"/>
                </geometry>
            </collision>
        </link>
        <joint name="${arm_id}_finger_joint1" type="prismatic">
            <parent link="${arm_id}_hand" />
            <child link="${arm_id}_leftfinger" />
            <origin xyz="0 0 0.0584" rpy="0 0 0" />
            <axis xyz="0 1 0" />
            <limit effort="100" lower="0.0" upper="0.04" velocity="0.2" />
            <dynamics damping="0.3" />
        </joint>
        <joint name="${arm_id}_finger_joint2" type="prismatic">
            <parent link="${arm_id}_hand" />
            <child link="${arm_id}_rightfinger" />
            <origin xyz="0 0 0.0584" rpy="0 0 0" />
            <axis xyz="0 -1 0" />
            <limit effort="100" lower="0.0" upper="0.04" velocity="0.2" />
            <mimic joint="${arm_id}_finger_joint1" />
            <dynamics damping="0.3" />
        </joint>
    </xacro:macro>
</robot>
